{
  "module": "AI\\NoxPanel\\network_scanner_fixes.py",
  "timestamp": "2025-07-18T11:02:24.312041",
  "total_functions": 3,
  "test_cases": [
    {
      "name": "test_get_quick_status_positive",
      "reasoning": "Tests successful execution path with valid inputs",
      "input": {
        "self": "valid_self"
      },
      "expected": "success",
      "validates": "Normal operation flow"
    },
    {
      "name": "test_get_quick_status_edge_case",
      "reasoning": "Tests boundary conditions and edge cases",
      "input": {
        "self": "edge_self"
      },
      "expected": "handled_gracefully",
      "validates": "Edge case handling"
    },
    {
      "name": "test_get_quick_status_error",
      "reasoning": "Tests error handling with invalid inputs",
      "input": {
        "self": "invalid_self"
      },
      "expected": "appropriate_exception",
      "validates": "Error handling robustness"
    },
    {
      "name": "test__calculate_network_health_positive",
      "reasoning": "Tests successful execution path with valid inputs",
      "input": {
        "self": "valid_self"
      },
      "expected": "success",
      "validates": "Normal operation flow"
    },
    {
      "name": "test__calculate_network_health_edge_case",
      "reasoning": "Tests boundary conditions and edge cases",
      "input": {
        "self": "edge_self"
      },
      "expected": "handled_gracefully",
      "validates": "Edge case handling"
    },
    {
      "name": "test__calculate_network_health_error",
      "reasoning": "Tests error handling with invalid inputs",
      "input": {
        "self": "invalid_self"
      },
      "expected": "appropriate_exception",
      "validates": "Error handling robustness"
    },
    {
      "name": "test_get_network_topology_positive",
      "reasoning": "Tests successful execution path with valid inputs",
      "input": {
        "self": "valid_self"
      },
      "expected": "success",
      "validates": "Normal operation flow"
    },
    {
      "name": "test_get_network_topology_edge_case",
      "reasoning": "Tests boundary conditions and edge cases",
      "input": {
        "self": "edge_self"
      },
      "expected": "handled_gracefully",
      "validates": "Edge case handling"
    },
    {
      "name": "test_get_network_topology_error",
      "reasoning": "Tests error handling with invalid inputs",
      "input": {
        "self": "invalid_self"
      },
      "expected": "appropriate_exception",
      "validates": "Error handling robustness"
    }
  ]
}